<?xml version="1.0" encoding="utf-8"?>
<robot name="ugv_beast">

  <!-- Base footprint -->
  <link name="base_footprint"/>

  <!-- Base link -->
  <link name="base_link">
    <inertial>
      <origin xyz="0.0035 0 0.048" rpy="0 0 0"/>
      <mass value="2.032"/>
      <inertia ixx="0.00455" ixy="0" ixz="0" iyy="0.00640" iyz="0" izz="0.00806"/>
    </inertial>
    <visual>
      <origin xyz="0 0 0" rpy="-1.5708 0 0"/>
      <geometry>
        <mesh filename="package://robot_description/meshes/base_link.stl"/>
      </geometry>
    </visual>
    <collision>
      <origin xyz="0 0 0" rpy="-1.5708 0 0"/>
      <geometry>
        <mesh filename="package://robot_description/meshes/base_link.stl"/>
      </geometry>
    </collision>
  </link>

  <joint name="base_joint" type="fixed">
    <parent link="base_footprint"/>
    <child link="base_link"/>
    <origin xyz="0 0 0.08" rpy="0 0 0"/>
  </joint>

  <!-- IMU link -->
  <link name="base_imu_link"/>
  <joint name="imu_joint" type="fixed">
    <parent link="base_link"/>
    <child link="base_imu_link"/>
    <origin xyz="0 0 0" rpy="0 0 0"/>
  </joint>

  <!-- Left wheels -->
  <link name="left_up_wheel_link">
    <visual>
      <origin xyz="0 0 0" rpy="-1.5708 0 0"/>
      <geometry><mesh filename="package://robot_description/meshes/left_up_wheel_link.stl"/></geometry>
    </visual>
    <collision>
      <origin xyz="0 0 0" rpy="-1.5708 0 0"/>
      <geometry><mesh filename="package://robot_description/meshes/left_up_wheel_link.stl"/></geometry>
    </collision>
  </link>
  <joint name="left_up_wheel_link_joint" type="continuous">
    <parent link="base_link"/>
    <child link="left_up_wheel_link"/>
    <origin xyz="0.0832 0.0619 0.0261" rpy="0 0 0"/>
    <axis xyz="0 -1 0"/>
  </joint>

  <link name="left_down_wheel_link">
    <visual>
      <origin xyz="0 0 0" rpy="-1.5708 0 0"/>
      <geometry><mesh filename="package://robot_description/meshes/left_down_wheel_link.stl"/></geometry>
    </visual>
    <collision>
      <origin xyz="0 0 0" rpy="-1.5708 0 0"/>
      <geometry><mesh filename="package://robot_description/meshes/left_down_wheel_link.stl"/></geometry>
    </collision>
  </link>
  <joint name="left_down_wheel_link_joint" type="continuous">
    <parent link="base_link"/>
    <child link="left_down_wheel_link"/>
    <origin xyz="-0.0722 0.0707 0.0356" rpy="0 0 0"/>
    <axis xyz="0 -1 0"/>
  </joint>

  <!-- Right wheels -->
  <link name="right_up_wheel_link">
    <visual>
      <origin xyz="0 0 0" rpy="-1.5708 0 0"/>
      <geometry><mesh filename="package://robot_description/meshes/right_up_wheel_link.stl"/></geometry>
    </visual>
    <collision>
      <origin xyz="0 0 0" rpy="-1.5708 0 0"/>
      <geometry><mesh filename="package://robot_description/meshes/right_up_wheel_link.stl"/></geometry>
    </collision>
  </link>
  <joint name="right_up_wheel_link_joint" type="continuous">
    <parent link="base_link"/>
    <child link="right_up_wheel_link"/>
    <origin xyz="0.0832 -0.0619 0.0261" rpy="0 0 0"/>
    <axis xyz="0 -1 0"/>
  </joint>

  <link name="right_down_wheel_link">
    <visual>
      <origin xyz="0 0 0" rpy="-1.5708 0 0"/>
      <geometry><mesh filename="package://robot_description/meshes/right_down_wheel_link.stl"/></geometry>
    </visual>
    <collision>
      <origin xyz="0 0 0" rpy="-1.5708 0 0"/>
      <geometry><mesh filename="package://robot_description/meshes/right_down_wheel_link.stl"/></geometry>
    </collision>
  </link>
  <joint name="right_down_wheel_link_joint" type="continuous">
    <parent link="base_link"/>
    <child link="right_down_wheel_link"/>
    <origin xyz="-0.0722 -0.0707 0.0356" rpy="0 0 0"/>
    <axis xyz="0 1 0"/>
  </joint>

  <!-- Lidar -->
  <link name="base_lidar_link">
    <visual>
      <origin xyz="0 0 0" rpy="-1.5708 0 0"/>
      <geometry><mesh filename="package://robot_description/meshes/base_lidar_link.stl"/></geometry>
    </visual>
    <collision>
      <origin xyz="0 0 0" rpy="-1.5708 0 0"/>
      <geometry><mesh filename="package://robot_description/meshes/base_lidar_link.stl"/></geometry>
    </collision>
  </link>
  <joint name="base_lidar_link_joint" type="fixed">
    <parent link="base_link"/>
    <child link="base_lidar_link"/>
    <origin xyz="0.0444 0 0.0973" rpy="0 0 1.5708"/>
  </joint>

  <!-- 3D Camera -->
  <link name="3d_camera_link">
    <visual>
      <origin xyz="0 0 0" rpy="-1.5708 0 0"/>
      <geometry><mesh filename="package://robot_description/meshes/3d_camera_link.stl"/></geometry>
    </visual>
    <collision>
      <origin xyz="0 0 0" rpy="-1.5708 0 0"/>
      <geometry><mesh filename="package://robot_description/meshes/3d_camera_link.stl"/></geometry>
    </collision>
  </link>
  <joint name="3d_camera_link_joint" type="fixed">
    <parent link="base_link"/>
    <child link="3d_camera_link"/>
    <origin xyz="0.0699 0 0.0793" rpy="0 0 0"/>
  </joint>

</robot>
